Workbook

Sheet README
A1: Childhood Immunisation Coverage in Nigeria - analysis workbook
A2: Capstone: Assessment of Childhood Immunisation Coverage and Inequalities in Nigeria: A Data-Driven Public Health Analysis
A4: Topic | B4: Detail
A5: Source | B5: WHO/UNICEF WUENIC 2025 revision, survey-data file (all countries). Nigeria rows extracted unchanged to Raw_Nigeria. Source file name: survey-data_wuenic2025rev.xlsx.
A6: What the file covers | B6: 1,140 Nigeria records from 22 surveys (birth cohorts 1984-2022), by vaccine, evidence type and age group, national level only.
A7: What it does not cover | B7: States, urban/rural, wealth, education or sex of the child. Geography and inequality aims need extra data (see Findings, section C).
A8: Standard definition used | B8: Children aged 12-23 months, evidence = 'Record or Recall', core vaccines BCG, DTP1, DTP3, POL3, MCV1, FULL (Clean_Data: Standard_Comparable = 1).
A9: Guide step 3 - clean | B9: Raw_Nigeria > Clean_Data (formulas) and Cleaning_Log.
A10: Guide step 4 - coverage | B10: Coverage sheet (coverage, dropout, zero-dose proxy, margin of error).
A11: Guide step 5 - compare | B11: Summary (years, survey families), Benchmark (bordering countries). Only countries exist as locations in this file.
A12: Guide step 6 - tables and charts | B12: Summary (4 tables, 5 charts), Benchmark chart, Trend_Data (chart feeders).
A13: Guide step 7 - dashboard | B13: Power_BI_Guide. The .pbix itself must be built in Power BI Desktop; Clean_Data and Surveys are the tables to load.
A14: Guide step 8 - interpret | B14: Findings (live-formula sentences, recommendations, limits).
A15: Assumptions | B15: Design effect = 2.0 (Coverage!B3, yellow cell, blue text). It is an assumption, not source data, and only drives margins of error.
... A18: Important caveat | B18: All values are crude survey estimates (validity = CRUDE), not the official WHO/UNICEF national estimates.
A21: Clean_Data column dictionary
A22: Survey / Survey_Family | B22: Cleaned survey name and its family (DHS, MICS, Coverage survey, Nutrition survey, Other).
A23: Collect_*_Year / Month | B23: Fieldwork dates split out; placeholder months (above 12) left blank.
A24: Cohort_Year | B24: Birth cohort the estimate refers to (not the survey year).
A25: Coverage_Pct / Denominator_n / Cards_Seen_Pct | B25: Coverage %, number of children, and % with a card seen (blank if not reported).
A26: Population_Group, In_Scope_Child, Standard_Comparable, Core_Vaccine, DHS_or_MICS | B26: Flags used to filter the analysis sets.
A27: Key_Count | B27: Rows sharing the same survey, cohort, vaccine, evidence and ages; should be 1.

Sheet Raw_Nigeria
A1: ISO3 | B1: surveyNameEnglish | C1: surveyNameProduction | D1: collectBegin | E1: collectEnd | F1: cohortYear | G1: vaccine | H1: evidence | I1: cardsSeen | J1: validity | K1: ageVaccination | L1: ageInterview | M1: coverage | N1: denominator
A2: NGA | C2: Status report on revised EPI programme from 1985 to 1989 | D2: 1985-98 | E2: 1985-98 | F2: 1984 | G2: BCG | H2: Record or Recall | J2: CRUDE | K2: 0-23 m | L2: 12-23 m | M2: 16.5
A3: NGA | C3: Status report on revised EPI programme from 1985 to 1989 | D3: 1985-98 | E3: 1985-98 | F3: 1984 | G3: DTP3 | H3: Record or Recall | J3: CRUDE | K3: 0-23 m | L3: 12-23 m | M3: 8.9
A4: NGA | C4: Status report on revised EPI programme from 1985 to 1989 | D4: 1985-98 | E4: 1985-98 | F4: 1984 | G4: MCV1 | H4: Record or Recall | J4: CRUDE | K4: 0-23 m | L4: 12-23 m | M4: 9.1
A5: NGA | C5: Status report on revised EPI programme from 1985 to 1989 | D5: 1985-98 | E5: 1985-98 | F5: 1984 | G5: POL3 | H5: Record or Recall | J5: CRUDE | K5: 0-23 m | L5: 12-23 m | M5: 8.1
A6: NGA | C6: Status report on revised EPI programme from 1985 to 1989 | D6: 1985-98 | E6: 1985-98 | F6: 1984 | G6: TT1 | H6: Record or Recall | J6: CRUDE | L6: CBAW | M6: 11.1
A7: NGA | C7: Status report on revised EPI programme from 1985 to 1989 | D7: 1985-98 | E7: 1985-98 | F7: 1984 | G7: TT2+ | H7: Record or Recall | J7: CRUDE | L7: CBAW | M7: 7
A8: NGA | C8: Status report on revised EPI programme from 1985 to 1989 | D8: 1986-98 | E8: 1986-98 | F8: 1985 | G8: BCG | H8: Record or Recall | J8: CRUDE | K8: 0-23 m | L8: 12-23 m | M8: 28.3
A9: NGA | C9: Status report on revised EPI programme from 1985 to 1989 | D9: 1986-98 | E9: 1986-98 | F9: 1985 | G9: DTP3 | H9: Record or Recall | J9: CRUDE | K9: 0-23 m | L9: 12-23 m | M9: 15.9
A10: NGA | C10: Status report on revised EPI programme from 1985 to 1989 | D10: 1986-98 | E10: 1986-98 | F10: 1985 | G10: MCV1 | H10: Record or Recall | J10: CRUDE | K10: 0-23 m | L10: 12-23 m | M10: 17.2
A11: NGA | C11: Status report on revised EPI programme from 1985 to 1989 | D11: 1986-98 | E11: 1986-98 | F11: 1985 | G11: POL3 | H11: Record or Recall | J11: CRUDE | K11: 0-23 m | L11: 12-23 m | M11: 16.3
A12: NGA | C12: Status report on revised EPI programme from 1985 to 1989 | D12: 1986-98 | E12: 1986-98 | F12: 1985 | G12: TT1 | H12: Record or Recall | J12: CRUDE | L12: CBAW | M12: 17.4
A13: NGA | C13: Status report on revised EPI programme from 1985 to 1989 | D13: 1986-98 | E13: 1986-98 | F13: 1985 | G13: TT2+ | H13: Record or Recall | J13: CRUDE | L13: CBAW | M13: 17.4
A14: NGA | C14: Status report on revised EPI programme from 1985 to 1989 | D14: 1987-98 | E14: 1987-98 | F14: 1986 | G14: BCG | H14: Record or Recall | J14: CRUDE | K14: 0-23 m | L14: 12-23 m | M14: 40
A15: NGA | C15: Nigeria Demographic and Health Survey 1990, 1992 | D15: 1990-04 | E15: 1990-10 | F15: 1986 | G15: BCG | H15: Record or Recall<12m | J15: CRUDE | K15: 0-12 m | L15: 48-59 m | M15: 30.4 | N15: 1349
A16: NGA | C16: Nigeria Demographic and Health Survey 1990, 1992 | D16: 1990-04 | E16: 1990-10 | F16: 1986 | G16: DTP1 | H16: Record or Recall<12m | J16: CRUDE | K16: 0-12 m | L16: 48-59 m | M16: 27 | N16: 1349
A17: NGA | C17: Status report on revised EPI programme from 1985 to 1989 | D17: 1987-98 | E17: 1987-98 | F17: 1986 | G17: DTP3 | H17: Record or Recall | J17: CRUDE | K17: 0-23 m | L17: 12-23 m | M17: 21.5
A18: NGA | C18: Nigeria Demographic and Health Survey 1990, 1992 | D18: 1990-04 | E18: 1990-10 | F18: 1986 | G18: DTP3 | H18: Record or Recall<12m | J18: CRUDE | K18: 0-12 m | L18: 48-59 m | M18: 16.6 | N18: 1349
A19: NGA | C19: Nigeria Demographic and Health Survey 1990, 1992 | D19: 1990-04 | E19: 1990-10 | F19: 1986 | G19: FULL | H19: Record or Recall<12m | J19: CRUDE | K19: 0-12 m | L19: 48-59 m | M19: 11.2 | N19: 1349
A20: NGA | C20: Status report on revised EPI programme from 1985 to 1989 | D20: 1987-98 | E20: 1987-98 | F20: 1986 | G20: MCV1 | H20: Record or Recall | J20: CRUDE | K20: 0-23 m | L20: 12-23 m | M20: 28
A21: NGA | C21: Nigeria Demographic and Health Survey 1990, 1992 | D21: 1990-04 | E21: 1990-10 | F21: 1986 | G21: MCV1 | H21: Record or Recall<12m | J21: CRUDE | K21: 0-12 m | L21: 48-59 m | M21: 15.8 | N21: 1349
A22: NGA | C22: Nigeria Demographic and Health Survey 1990, 1992 | D22: 1990-04 | E22: 1990-10 | F22: 1986 | G22: POL1 | H22: Record or Recall<12m | J22: CRUDE | K22: 0-12 m | L22: 48-59 m | M22: 27.1 | N22: 1349
A23: NGA | C23: Status report on revised EPI programme from 1985 to 1989 | D23: 1987-98 | E23: 1987-98 | F23: 1986 | G23: POL3 | H23: Record or Recall | J23: CRUDE | K23: 0-23 m | L23: 12-23 m | M23: 20.7
A24: NGA | C24: Nigeria Demographic and Health Survey 1990, 1992 | D24: 1990-04 | E24: 1990-10 | F24: 1986 | G24: POL3 | H24: Record or Recall<12m | J24: CRUDE | K24: 0-12 m | L24: 48-59 m | M24: 16.5 | N24: 1349
A25: NGA | C25: Status report on revised EPI programme from 1985 to 1989 | D25: 1987-98 | E25: 1987-98 | F25: 1986 | G25: TT1 | H25: Record or Recall | J25: CRUDE | L25: CBAW | M25: 21.7
A26: NGA | C26: Status report on revised EPI programme from 1985 to 1989 | D26: 1987-98 | E26: 1987-98 | F26: 1986 | G26: TT2+ | H26: Record or Recall | J26: CRUDE | L26: CBAW | M26: 22
A27: NGA | C27: EPI, Immunization Coverage Survey, 1988 | D27: 1988-98 | E27: 1988-98 | F27: 1987 | G27: BCG | H27: Record | J27: CRUDE | K27: 0-23 m | L27: 12-23 m | M27: 52.9 | N27: 9240
A28: NGA | C28: EPI, Immunization Coverage Survey, 1988 | D28: 1988-98 | E28: 1988-98 | F28: 1987 | G28: BCG | H28: Record or Recall | J28: CRUDE | K28: 0-23 m | L28: 12-23 m | M28: 72.2 | N28: 9240
A29: NGA | C29: EPI, Immunization Coverage Survey, 1988 | D29: 1988-98 | E29: 1988-98 | F29: 1987 | G29: BCG | H29: Recall | J29: CRUDE | K29: 0-23 m | L29: 12-23 m | M29: 19.3 | N29: 9240
A30: NGA | C30: Nigeria Demographic and Health Survey 1990, 1992 | D30: 1990-04 | E30: 1990-10 | F30: 1987 | G30: BCG | H30: Record or Recall<12m | J30: CRUDE | K30: 0-12 m | L30: 36-47 m | M30: 34.9 | N30: 1415
A31: NGA | C31: Nigeria Demographic and Health Survey 1990, 1992 | D31: 1990-04 | E31: 1990-10 | F31: 1987 | G31: DTP1 | H31: Record or Recall<12m | J31: CRUDE | K31: 0-12 m | L31: 36-47 m | M31: 33.8 | N31: 1415
A32: NGA | C32: EPI, Immunization Coverage Survey, 1988 | D32: 1988-98 | E32: 1988-98 | F32: 1987 | G32: DTP3 | H32: Record | J32: CRUDE | K32: 0-23 m | L32: 12-23 m | M32: 41.9 | N32: 9240
A33: NGA | C33: EPI, Immunization Coverage Survey, 1988 | D33: 1988-98 | E33: 1988-98 | F33: 1987 | G33: DTP3 | H33: Record or Recall | J33: CRUDE | K33: 0-23 m | L33: 12-23 m | M33: 57.8 | N33: 9240
A34: NGA | C34: EPI, Immunization Coverage Survey, 1988 | D34: 1988-98 | E34: 1988-98 | F34: 1987 | G34: DTP3 | H34: Recall | J34: CRUDE | K34: 0-23 m | L34: 12-23 m | M34: 15.9 | N34: 9240
A35: NGA | C35: Nigeria Demographic and Health Survey 1990, 1992 | D35: 1990-04 | E35: 1990-10 | F35: 1987 | G35: DTP3 | H35: Record or Recall<12m | J35: CRUDE | K35: 0-12 m | L35: 36-47 m | M35: 22.7 | N35: 1415
A36: NGA | C36: EPI, Immunization Coverage Survey, 1988 | D36: 1988-98 | E36: 1988-98 | F36: 1987 | G36: FULL | H36: Record | J36: CRUDE | K36: 0-23 m | L36: 12-23 m | M36: 25.6 | N36: 9240
A37: NGA | C37: EPI, Immunization Coverage Survey, 1988 | D37: 1988-98 | E37: 1988-98 | F37: 1987 | G37: FULL | H37: Record or Recall | J37: CRUDE | K37: 0-23 m | L37: 12-23 m | M37: 37.5 | N37: 9240
A38: NGA | C38: EPI, Immunization Coverage Survey, 1988 | D38: 1988-98 | E38: 1988-98 | F38: 1987 | G38: FULL | H38: Recall | J38: CRUDE | K38: 0-23 m | L38: 12-23 m | M38: 11.9 | N38: 9240
... A48: NGA | C48: Nigeria Demographic and Health Survey 1990, 1992 | D48: 1990-04 | E48: 1990-10 | F48: 1987 | G48: POL3 | H48: Record or Recall<12m | J48: CRUDE | K48: 0-12 m | L48: 36-47 m | M48: 22.6 | N48: 1415
A49: NGA | C49: WHO/EPI/CEIS/90.1 | D49: 1988-98 | E49: 1988-98 | F49: 1987 | G49: TT2+ | H49: NOT USED | J49: CRUDE | L49: CBAW | M49: 16
...

Sheet Clean_Data
A1: Row_ID | B1: Survey | C1: Survey_Family | D1: Collect_Begin_Year | E1: Collect_Begin_Month | F1: Collect_End_Year | G1: Collect_End_Month | H1: Cohort_Year | I1: Vaccine | J1: Evidence | K1: Age_Interview | L1: Age_Vaccination | M1: Cards_Seen_Pct | N1: Coverage_Pct | O1: Denominator_n | P1: Population_Group | Q1: Evidence_Not_Used | R1: In_Scope_Child | S1: Standard_Comparable | T1: Core_Vaccine | U1: DHS_or_MICS | V1: Missing_Denominator | W1: Missing_CardsSeen | X1: Key_Count
A2: =ROW()-1 -> 1 | B2: =IF(Raw_Nigeria!B2="",TRIM(Raw_Nigeria!C2),TRIM(Raw_Nigeria!B2)) -> Status report on revised EPI programme from 1985 to 1989 | C2: =IF(ISNUMBER(SEARCH("Demographic and Health",B2)),"DHS",IF(OR(ISNUMBER(SEARCH("Multiple Indicator Cluster",B2)),ISNUMBER(SEARCH("MICS",B2))),"MICS",IF(ISNUMBER(SEARCH("Immunization Coverage Survey",B2)),"Coverage survey",IF(ISNUMBER(SEARCH("Nutrition",B2)),"Nutrition survey","Other")))) -> Other | D2: =VALUE(LEFT(Raw_Nigeria!D2,4)) -> 1985 | E2: =IF(VALUE(RIGHT(Raw_Nigeria!D2,2))>12,"",VALUE(RIGHT(Raw_Nigeria!D2,2))) | F2: =VALUE(LEFT(Raw_Nigeria!E2,4)) -> 1985 | G2: =IF(VALUE(RIGHT(Raw_Nigeria!E2,2))>12,"",VALUE(RIGHT(Raw_Nigeria!E2,2))) | H2: =Raw_Nigeria!F2 -> 1984 | I2: =UPPER(TRIM(Raw_Nigeria!G2)) -> BCG | J2: =Raw_Nigeria!H2 -> Record or Recall | K2: =Raw_Nigeria!L2 -> 12-23 m | L2: =IF(Raw_Nigeria!K2="","n/a",Raw_Nigeria!K2) -> 0-23 m | M2: =IF(Raw_Nigeria!I2="","",Raw_Nigeria!I2) | N2: =Raw_Nigeria!M2 -> 16.5 | O2: =IF(Raw_Nigeria!N2="","",Raw_Nigeria!N2) | P2: =IF(K2="CBAW","Women of child-bearing age","Children") -> Children | Q2: =IF(J2="NOT USED",1,0) -> 0 | R2: =IF(AND(P2="Children",Q2=0),1,0) -> 1 | S2: =IF(AND(R2=1,J2="Record or Recall",K2="12-23 m"),1,0) -> 1 | T2: =IF(OR(I2="BCG",I2="DTP1",I2="DTP3",I2="POL3",I2="MCV1",I2="FULL"),1,0) -> 1 | U2: =IF(OR(C2="DHS",C2="MICS"),1,0) -> 0 | V2: =IF(O2="",1,0) -> 1 | W2: =IF(M2="",1,0) -> 1 | X2: =COUNTIFS($B$2:$B$1141,B2,$H$2:$H$1141,H2,$I$2:$I$1141,I2,$J$2:$J$1141,J2,$K$2:$K$1141,K2,$L$2:$L$1141,L2) -> 1
A3: =ROW()-1 -> 2 | B3: =IF(Raw_Nigeria!B3="",TRIM(Raw_Nigeria!C3),TRIM(Raw_Nigeria!B3)) -> Status report on revised EPI programme from 1985 to 1989 | C3: =IF(ISNUMBER(SEARCH("Demographic and Health",B3)),"DHS",IF(OR(ISNUMBER(SEARCH("Multiple Indicator Cluster",B3)),ISNUMBER(SEARCH("MICS",B3))),"MICS",IF(ISNUMBER(SEARCH("Immunization Coverage Survey",B3)),"Coverage survey",IF(ISNUMBER(SEARCH("Nutrition",B3)),"Nutrition survey","Other")))) -> Other | D3: =VALUE(LEFT(Raw_Nigeria!D3,4)) -> 1985 | E3: =IF(VALUE(RIGHT(Raw_Nigeria!D3,2))>12,"",VALUE(RIGHT(Raw_Nigeria!D3,2))) | F3: =VALUE(LEFT(Raw_Nigeria!E3,4)) -> 1985 | G3: =IF(VALUE(RIGHT(Raw_Nigeria!E3,2))>12,"",VALUE(RIGHT(Raw_Nigeria!E3,2))) | H3: =Raw_Nigeria!F3 -> 1984 | I3: =UPPER(TRIM(Raw_Nigeria!G3)) -> DTP3 | J3: =Raw_Nigeria!H3 -> Record or Recall | K3: =Raw_Nigeria!L3 -> 12-23 m | L3: =IF(Raw_Nigeria!K3="","n/a",Raw_Nigeria!K3) -> 0-23 m | M3: =IF(Raw_Nigeria!I3="","",Raw_Nigeria!I3) | N3: =Raw_Nigeria!M3 -> 8.9 | O3: =IF(Raw_Nigeria!N3="","",Raw_Nigeria!N3) | P3: =IF(K3="CBAW","Women of child-bearing age","Children") -> Children | Q3: =IF(J3="NOT USED",1,0) -> 0 | R3: =IF(AND(P3="Children",Q3=0),1,0) -> 1 | S3: =IF(AND(R3=1,J3="Record or Recall",K3="12-23 m"),1,0) -> 1 | T3: =IF(OR(I3="BCG",I3="DTP1",I3="DTP3",I3="POL3",I3="MCV1",I3="FULL"),1,0) -> 1 | U3: =IF(OR(C3="DHS",C3="MICS"),1,0) -> 0 | V3: =IF(O3="",1,0) -> 1 | W3: =IF(M3="",1,0) -> 1 | X3: =COUNTIFS($B$2:$B$1141,B3,$H$2:$H$1141,H3,$I$2:$I$1141,I3,$J$2:$J$1141,J3,$K$2:$K$1141,K3,$L$2:$L$1141,L3) -> 1
A4: =ROW()-1 -> 3 | B4: =IF(Raw_Nigeria!B4="",TRIM(Raw_Nigeria!C4),TRIM(Raw_Nigeria!B4)) -> Status report on revised EPI programme from 1985 to 1989 | C4: =IF(ISNUMBER(SEARCH("Demographic and Health",B4)),"DHS",IF(OR(ISNUMBER(SEARCH("Multiple Indicator Cluster",B4)),ISNUMBER(SEARCH("MICS",B4))),"MICS",IF(ISNUMBER(SEARCH("Immunization Coverage Survey",B4)),"Coverage survey",IF(ISNUMBER(SEARCH("Nutrition",B4)),"Nutrition survey","Other")))) -> Other | D4: =VALUE(LEFT(Raw_Nigeria!D4,4)) -> 1985 | E4: =IF(VALUE(RIGHT(Raw_Nigeria!D4,2))>12,"",VALUE(RIGHT(Raw_Nigeria!D4,2))) | F4: =VALUE(LEFT(Raw_Nigeria!E4,4)) -> 1985 | G4: =IF(VALUE(RIGHT(Raw_Nigeria!E4,2))>12,"",VALUE(RIGHT(Raw_Nigeria!E4,2))) | H4: =Raw_Nigeria!F4 -> 1984 | I4: =UPPER(TRIM(Raw_Nigeria!G4)) -> MCV1 | J4: =Raw_Nigeria!H4 -> Record or Recall | K4: =Raw_Nigeria!L4 -> 12-23 m | L4: =IF(Raw_Nigeria!K4="","n/a",Raw_Nigeria!K4) -> 0-23 m | M4: =IF(Raw_Nigeria!I4="","",Raw_Nigeria!I4) | N4: =Raw_Nigeria!M4 -> 9.1 | O4: =IF(Raw_Nigeria!N4="","",Raw_Nigeria!N4) | P4: =IF(K4="CBAW","Women of child-bearing age","Children") -> Children | Q4: =IF(J4="NOT USED",1,0) -> 0 | R4: =IF(AND(P4="Children",Q4=0),1,0) -> 1 | S4: =IF(AND(R4=1,J4="Record or Recall",K4="12-23 m"),1,0) -> 1 | T4: =IF(OR(I4="BCG",I4="DTP1",I4="DTP3",I4="POL3",I4="MCV1",I4="FULL"),1,0) -> 1 | U4: =IF(OR(C4="DHS",C4="MICS"),1,0) -> 0 | V4: =IF(O4="",1,0) -> 1 | W4: =IF(M4="",1,0) -> 1 | X4: =COUNTIFS($B$2:$B$1141,B4,$H$2:$H$1141,H4,$I$2:$I$1141,I4,$J$2:$J$1141,J4,$K$2:$K$1141,K4,$L$2:$L$1141,L4) -> 1
A5: =ROW()-1 -> 4 | B5: =IF(Raw_Nigeria!B5="",TRIM(Raw_Nigeria!C5),TRIM(Raw_Nigeria!B5)) -> Status report on revised EPI programme from 1985 to 1989 | C5: =IF(ISNUMBER(SEARCH("Demographic and Health",B5)),"DHS",IF(OR(ISNUMBER(SEARCH("Multiple Indicator Cluster",B5)),ISNUMBER(SEARCH("MICS",B5))),"MICS",IF(ISNUMBER(SEARCH("Immunization Coverage Survey",B5)),"Coverage survey",IF(ISNUMBER(SEARCH("Nutrition",B5)),"Nutrition survey","Other")))) -> Other | D5: =VALUE(LEFT(Raw_Nigeria!D5,4)) -> 1985 | E5: =IF(VALUE(RIGHT(Raw_Nigeria!D5,2))>12,"",VALUE(RIGHT(Raw_Nigeria!D5,2))) | F5: =VALUE(LEFT(Raw_Nigeria!E5,4)) -> 1985 | G5: =IF(VALUE(RIGHT(Raw_Nigeria!E5,2))>12,"",VALUE(RIGHT(Raw_Nigeria!E5,2))) | H5: =Raw_Nigeria!F5 -> 1984 | I5: =UPPER(TRIM(Raw_Nigeria!G5)) -> POL3 | J5: =Raw_Nigeria!H5 -> Record or Recall | K5: =Raw_Nigeria!L5 -> 12-23 m | L5: =IF(Raw_Nigeria!K5="","n/a",Raw_Nigeria!K5) -> 0-23 m | M5: =IF(Raw_Nigeria!I5="","",Raw_Nigeria!I5) | N5: =Raw_Nigeria!M5 -> 8.1 | O5: =IF(Raw_Nigeria!N5="","",Raw_Nigeria!N5) | P5: =IF(K5="CBAW","Women of child-bearing age","Children") -> Children | Q5: =IF(J5="NOT USED",1,0) -> 0 | R5: =IF(AND(P5="Children",Q5=0),1,0) -> 1 | S5: =IF(AND(R5=1,J5="Record or Recall",K5="12-23 m"),1,0) -> 1 | T5: =IF(OR(I5="BCG",I5="DTP1",I5="DTP3",I5="POL3",I5="MCV1",I5="FULL"),1,0) -> 1 | U5: =IF(OR(C5="DHS",C5="MICS"),1,0) -> 0 | V5: =IF(O5="",1,0) -> 1 | W5: =IF(M5="",1,0) -> 1 | X5: =COUNTIFS($B$2:$B$1141,B5,$H$2:$H$1141,H5,$I$2:$I$1141,I5,$J$2:$J$1141,J5,$K$2:$K$1141,K5,$L$2:$L$1141,L5) -> 1
A6: =ROW()-1 -> 5 | B6: =IF(Raw_Nigeria!B6="",TRIM(Raw_Nigeria!C6),TRIM(Raw_Nigeria!B6)) -> Status report on revised EPI programme from 1985 to 1989 | C6: =IF(ISNUMBER(SEARCH("Demographic and Health",B6)),"DHS",IF(OR(ISNUMBER(SEARCH("Multiple Indicator Cluster",B6)),ISNUMBER(SEARCH("MICS",B6))),"MICS",IF(ISNUMBER(SEARCH("Immunization Coverage Survey",B6)),"Coverage survey",IF(ISNUMBER(SEARCH("Nutrition",B6)),"Nutrition survey","Other")))) -> Other | D6: =VALUE(LEFT(Raw_Nigeria!D6,4)) -> 1985 | E6: =IF(VALUE(RIGHT(Raw_Nigeria!D6,2))>12,"",VALUE(RIGHT(Raw_Nigeria!D6,2))) | F6: =VALUE(LEFT(Raw_Nigeria!E6,4)) -> 1985 | G6: =IF(VALUE(RIGHT(Raw_Nigeria!E6,2))>12,"",VALUE(RIGHT(Raw_Nigeria!E6,2))) | H6: =Raw_Nigeria!F6 -> 1984 | I6: =UPPER(TRIM(Raw_Nigeria!G6)) -> TT1 | J6: =Raw_Nigeria!H6 -> Record or Recall | K6: =Raw_Nigeria!L6 -> CBAW | L6: =IF(Raw_Nigeria!K6="","n/a",Raw_Nigeria!K6) -> n/a | M6: =IF(Raw_Nigeria!I6="","",Raw_Nigeria!I6) | N6: =Raw_Nigeria!M6 -> 11.1 | O6: =IF(Raw_Nigeria!N6="","",Raw_Nigeria!N6) | P6: =IF(K6="CBAW","Women of child-bearing age","Children") -> Women of child-bearing age | Q6: =IF(J6="NOT USED",1,0) -> 0 | R6: =IF(AND(P6="Children",Q6=0),1,0) -> 0 | S6: =IF(AND(R6=1,J6="Record or Recall",K6="12-23 m"),1,0) -> 0 | T6: =IF(OR(I6="BCG",I6="DTP1",I6="DTP3",I6="POL3",I6="MCV1",I6="FULL"),1,0) -> 0 | U6: =IF(OR(C6="DHS",C6="MICS"),1,0) -> 0 | V6: =IF(O6="",1,0) -> 1 | W6: =IF(M6="",1,0) -> 1 | X6: =COUNTIFS($B$2:$B$1141,B6,$H$2:$H$1141,H6,$I$2:$I$1141,I6,$J$2:$J$1141,J6,$K$2:$K$1141,K6,$L$2:$L$1141,L6) -> 1
A7: =ROW()-1 -> 6 | B7: =IF(Raw_Nigeria!B7="",TRIM(Raw_Nigeria!C7),TRIM(Raw_Nigeria!B7)) -> Status report on revised EPI programme from 1985 to 1989 | C7: =IF(ISNUMBER(SEARCH("Demographic and Health",B7)),"DHS",IF(OR(ISNUMBER(SEARCH("Multiple Indicator Cluster",B7)),ISNUMBER(SEARCH("MICS",B7))),"MICS",IF(ISNUMBER(SEARCH("Immunization Coverage Survey",B7)),"Coverage survey",IF(ISNUMBER(SEARCH("Nutrition",B7)),"Nutrition survey","Other")))) -> Other | D7: =VALUE(LEFT(Raw_Nigeria!D7,4)) -> 1985 | E7: =IF(VALUE(RIGHT(Raw_Nigeria!D7,2))>12,"",VALUE(RIGHT(Raw_Nigeria!D7,2))) | F7: =VALUE(LEFT(Raw_Nigeria!E7,4)) -> 1985 | G7: =IF(VALUE(RIGHT(Raw_Nigeria!E7,2))>12,"",VALUE(RIGHT(Raw_Nigeria!E7,2))) | H7: =Raw_Nigeria!F7 -> 1984 | I7: =UPPER(TRIM(Raw_Nigeria!G7)) -> TT2+ | J7: =Raw_Nigeria!H7 -> Record or Recall | K7: =Raw_Nigeria!L7 -> CBAW | L7: =IF(Raw_Nigeria!K7="","n/a",Raw_Nigeria!K7) -> n/a | M7: =IF(Raw_Nigeria!I7="","",Raw_Nigeria!I7) | N7: =Raw_Nigeria!M7 -> 7 | O7: =IF(Raw_Nigeria!N7="","",Raw_Nigeria!N7) | P7: =IF(K7="CBAW","Women of child-bearing age","Children") -> Women of child-bearing age | Q7: =IF(J7="NOT USED",1,0) -> 0 | R7: =IF(AND(P7="Children",Q7=0),1,0) -> 0 | S7: =IF(AND(R7=1,J7="Record or Recall",K7="12-23 m"),1,0) -> 0 | T7: =IF(OR(I7="BCG",I7="DTP1",I7="DTP3",I7="POL3",I7="MCV1",I7="FULL"),1,0) -> 0 | U7: =IF(OR(C7="DHS",C7="MICS"),1,0) -> 0 | V7: =IF(O7="",1,0) -> 1 | W7: =IF(M7="",1,0) -> 1 | X7: =COUNTIFS($B$2:$B$1141,B7,$H$2:$H$1141,H7,$I$2:$I$1141,I7,$J$2:$J$1141,J7,$K$2:$K$1141,K7,$L$2:$L$1141,L7) -> 1
A8: =ROW()-1 -> 7 | B8: =IF(Raw_Nigeria!B8="",TRIM(Raw_Nigeria!C8),TRIM(Raw_Nigeria!B8)) -> Status report on revised EPI programme from 1985 to 1989 | C8: =IF(ISNUMBER(SEARCH("Demographic and Health",B8)),"DHS",IF(OR(ISNUMBER(SEARCH("Multiple Indicator Cluster",B8)),ISNUMBER(SEARCH("MICS",B8))),"MICS",IF(ISNUMBER(SEARCH("Immunization Coverage Survey",B8)),"Coverage survey",IF(ISNUMBER(SEARCH("Nutrition",B8)),"Nutrition survey","Other")))) -> Other | D8: =VALUE(LEFT(Raw_Nigeria!D8,4)) -> 1986 | E8: =IF(VALUE(RIGHT(Raw_Nigeria!D8,2))>12,"",VALUE(RIGHT(Raw_Nigeria!D8,2))) | F8: =VALUE(LEFT(Raw_Nigeria!E8,4)) -> 1986 | G8: =IF(VALUE(RIGHT(Raw_Nigeria!E8,2))>12,"",VALUE(RIGHT(Raw_Nigeria!E8,2))) | H8: =Raw_Nigeria!F8 -> 1985 | I8: =UPPER(TRIM(Raw_Nigeria!G8)) -> BCG | J8: =Raw_Nigeria!H8 -> Record or Recall | K8: =Raw_Nigeria!L8 -> 12-23 m | L8: =IF(Raw_Nigeria!K8="","n/a",Raw_Nigeria!K8) -> 0-23 m | M8: =IF(Raw_Nigeria!I8="","",Raw_Nigeria!I8) | N8: =Raw_Nigeria!M8 -> 28.3 | O8: =IF(Raw_Nigeria!N8="","",Raw_Nigeria!N8) | P8: =IF(K8="CBAW","Women of child-bearing age","Children") -> Children | Q8: =IF(J8="NOT USED",1,0) -> 0 | R8: =IF(AND(P8="Children",Q8=0),1,0) -> 1 | S8: =IF(AND(R8=1,J8="Record or Recall",K8="12-23 m"),1,0) -> 1 | T8: =IF(OR(I8="BCG",I8="DTP1",I8="DTP3",I8="POL3",I8="MCV1",I8="FULL"),1,0) -> 1 | U8: =IF(OR(C8="DHS",C8="MICS"),1,0) -> 0 | V8: =IF(O8="",1,0) -> 1 | W8: =IF(M8="",1,0) -> 1 | X8: =COUNTIFS($B$2:$B$1141,B8,$H$2:$H$1141,H8,$I$2:$I$1141,I8,$J$2:$J$1141,J8,$K$2:$K$1141,K8,$L$2:$L$1141,L8) -> 1
A9: =ROW()-1 -> 8 | B9: =IF(Raw_Nigeria!B9="",TRIM(Raw_Nigeria!C9),TRIM(Raw_Nigeria!B9)) -> Status report on revised EPI programme from 1985 to 1989 | C9: =IF(ISNUMBER(SEARCH("Demographic and Health",B9)),"DHS",IF(OR(ISNUMBER(SEARCH("Multiple Indicator Cluster",B9)),ISNUMBER(SEARCH("MICS",B9))),"MICS",IF(ISNUMBER(SEARCH("Immunization Coverage Survey",B9)),"Coverage survey",IF(ISNUMBER(SEARCH("Nutrition",B9)),"Nutrition survey","Other")))) -> Other | D9: =VALUE(LEFT(Raw_Nigeria!D9,4)) -> 1986 | E9: =IF(VALUE(RIGHT(Raw_Nigeria!D9,2))>12,"",VALUE(RIGHT(Raw_Nigeria!D9,2))) | F9: =VALUE(LEFT(Raw_Nigeria!E9,4)) -> 1986 | G9: =IF(VALUE(RIGHT(Raw_Nigeria!E9,2))>12,"",VALUE(RIGHT(Raw_Nigeria!E9,2))) | H9: =Raw_Nigeria!F9 -> 1985 | I9: =UPPER(TRIM(Raw_Nigeria!G9)) -> DTP3 | J9: =Raw_Nigeria!H9 -> Record or Recall | K9: =Raw_Nigeria!L9 -> 12-23 m | L9: =IF(Raw_Nigeria!K9="","n/a",Raw_Nigeria!K9) -> 0-23 m | M9: =IF(Raw_Nigeria!I9="","",Raw_Nigeria!I9) | N9: =Raw_Nigeria!M9 -> 15.9 | O9: =IF(Raw_Nigeria!N9="","",Raw_Nigeria!N9) | P9: =IF(K9="CBAW","Women of child-bearing age","Children") -> Children | Q9: =IF(J9="NOT USED",1,0) -> 0 | R9: =IF(AND(P9="Children",Q9=0),1,0) -> 1 | S9: =IF(AND(R9=1,J9="Record or Recall",K9="12-23 m"),1,0) -> 1 | T9: =IF(OR(I9="BCG",I9="DTP1",I9="DTP3",I9="POL3",I9="MCV1",I9="FULL"),1,0) -> 1 | U9: =IF(OR(C9="DHS",C9="MICS"),1,0) -> 0 | V9: =IF(O9="",1,0) -> 1 | W9: =IF(M9="",1,0) -> 1 | X9: =COUNTIFS($B$2:$B$1141,B9,$H$2:$H$1141,H9,$I$2:$I$1141,I9,$J$2:$J$1141,J9,$K$2:$K$1141,K9,$L$2:$L$1141,L9) -> 1
A10: =ROW()-1 -> 9 | B10: =IF(Raw_Nigeria!B10="",TRIM(Raw_Nigeria!C10),TRIM(Raw_Nigeria!B10)) -> Status report on revised EPI programme from 1985 to 1989 | C10: =IF(ISNUMBER(SEARCH("Demographic and Health",B10)),"DHS",IF(OR(ISNUMBER(SEARCH("Multiple Indicator Cluster",B10)),ISNUMBER(SEARCH("MICS",B10))),"MICS",IF(ISNUMBER(SEARCH("Immunization Coverage Survey",B10)),"Coverage survey",IF(ISNUMBER(SEARCH("Nutrition",B10)),"Nutrition survey","Other")))) -> Other | D10: =VALUE(LEFT(Raw_Nigeria!D10,4)) -> 1986 | E10: =IF(VALUE(RIGHT(Raw_Nigeria!D10,2))>12,"",VALUE(RIGHT(Raw_Nigeria!D10,2))) | F10: =VALUE(LEFT(Raw_Nigeria!E10,4)) -> 1986 | G10: =IF(VALUE(RIGHT(Raw_Nigeria!E10,2))>12,"",VALUE(RIGHT(Raw_Nigeria!E10,2))) | H10: =Raw_Nigeria!F10 -> 1985 | I10: =UPPER(TRIM(Raw_Nigeria!G10)) -> MCV1 | J10: =Raw_Nigeria!H10 -> Record or Recall | K10: =Raw_Nigeria!L10 -> 12-23 m | L10: =IF(Raw_Nigeria!K10="","n/a",Raw_Nigeria!K10) -> 0-23 m | M10: =IF(Raw_Nigeria!I10="","",Raw_Nigeria!I10) | N10: =Raw_Nigeria!M10 -> 17.2 | O10: =IF(Raw_Nigeria!N10="","",Raw_Nigeria!N10) | P10: =IF(K10="CBAW","Women of child-bearing age","Children") -> Children | Q10: =IF(J10="NOT USED",1,0) -> 0 | R10: =IF(AND(P10="Children",Q10=0),1,0) -> 1 | S10: =IF(AND(R10=1,J10="Record or Recall",K10="12-23 m"),1,0) -> 1 | T10: =IF(OR(I10="BCG",I10="DTP1",I10="DTP3",I10="POL3",I10="MCV1",I10="FULL"),1,0) -> 1 | U10: =IF(OR(C10="DHS",C10="MICS"),1,0) -> 0 | V10: =IF(O10="",1,0) -> 1 | W10: =IF(M10="",1,0) -> 1 | X10: =COUNTIFS($B$2:$B$1141,B10,$H$2:$H$1141,H10,$I$2:$I$1141,I10,$J$2:$J$1141,J10,$K$2:$K$1141,K10,$L$2:$L$1141,L10) -> 1
A11: =ROW()-1 -> 10 | B11: =IF(Raw_Nigeria!B11="",TRIM(Raw_Nigeria!C11),TRIM(Raw_Nigeria!B11)) -> Status report on revised EPI programme from 1985 to 1989 | C11: =IF(ISNUMBER(SEARCH("Demographic and Health",B11)),"DHS",IF(OR(ISNUMBER(SEARCH("Multiple Indicator Cluster",B11)),ISNUMBER(SEARCH("MICS",B11))),"MICS",IF(ISNUMBER(SEARCH("Immunization Coverage Survey",B11)),"Coverage survey",IF(ISNUMBER(SEARCH("Nutrition",B11)),"Nutrition survey","Other")))) -> Other | D11: =VALUE(LEFT(Raw_Nigeria!D11,4)) -> 1986 | E11: =IF(VALUE(RIGHT(Raw_Nigeria!D11,2))>12,"",VALUE(RIGHT(Raw_Nigeria!D11,2))) | F11: =VALUE(LEFT(Raw_Nigeria!E11,4)) -> 1986 | G11: =IF(VALUE(RIGHT(Raw_Nigeria!E11,2))>12,"",VALUE(RIGHT(Raw_Nigeria!E11,2))) | H11: =Raw_Nigeria!F11 -> 1985 | I11: =UPPER(TRIM(Raw_Nigeria!G11)) -> POL3 | J11: =Raw_Nigeria!H11 -> Record or Recall | K11: =Raw_Nigeria!L11 -> 12-23 m | L11: =IF(Raw_Nigeria!K11="","n/a",Raw_Nigeria!K11) -> 0-23 m | M11: =IF(Raw_Nigeria!I11="","",Raw_Nigeria!I11) | N11: =Raw_Nigeria!M11 -> 16.3 | O11: =IF(Raw_Nigeria!N11="","",Raw_Nigeria!N11) | P11: =IF(K11="CBAW","Women of child-bearing age","Children") -> Children | Q11: =IF(J11="NOT USED",1,0) -> 0 | R11: =IF(AND(P11="Children",Q11=0),1,0) -> 1 | S11: =IF(AND(R11=1,J11="Record or Recall",K11="12-23 m"),1,0) -> 1 | T11: =IF(OR(I11="BCG",I11="DTP1",I11="DTP3",I11="POL3",I11="MCV1",I11="FULL"),1,0) -> 1 | U11: =IF(OR(C11="DHS",C11="MICS"),1,0) -> 0 | V11: =IF(O11="",1,0) -> 1 | W11: =IF(M11="",1,0) -> 1 | X11: =COUNTIFS($B$2:$B$1141,B11,$H$2:$H$1141,H11,$I$2:$I$1141,I11,$J$2:$J$1141,J11,$K$2:$K$1141,K11,$L$2:$L$1141,L11) -> 1
A12: =ROW()-1 -> 11 | B12: =IF(Raw_Nigeria!B12="",TRIM(Raw_Nigeria!C12),TRIM(Raw_Nigeria!B12)) -> Status report on revised EPI programme from 1985 to 1989 | C12: =IF(ISNUMBER(SEARCH("Demographic and Health",B12)),"DHS",IF(OR(ISNUMBER(SEARCH("Multiple Indicator Cluster",B12)),ISNUMBER(SEARCH("MICS",B12))),"MICS",IF(ISNUMBER(SEARCH("Immunization Coverage Survey",B12)),"Coverage survey",IF(ISNUMBER(SEARCH("Nutrition",B12)),"Nutrition survey","Other")))) -> Other | D12: =VALUE(LEFT(Raw_Nigeria!D12,4)) -> 1986 | E12: =IF(VALUE(RIGHT(Raw_Nigeria!D12,2))>12,"",VALUE(RIGHT(Raw_Nigeria!D12,2))) | F12: =VALUE(LEFT(Raw_Nigeria!E12,4)) -> 1986 | G12: =IF(VALUE(RIGHT(Raw_Nigeria!E12,2))>12,"",VALUE(RIGHT(Raw_Nigeria!E12,2))) | H12: =Raw_Nigeria!F12 -> 1985 | I12: =UPPER(TRIM(Raw_Nigeria!G12)) -> TT1 | J12: =Raw_Nigeria!H12 -> Record or Recall | K12: =Raw_Nigeria!L12 -> CBAW | L12: =IF(Raw_Nigeria!K12="","n/a",Raw_Nigeria!K12) -> n/a | M12: =IF(Raw_Nigeria!I12="","",Raw_Nigeria!I12) | N12: =Raw_Nigeria!M12 -> 17.4 | O12: =IF(Raw_Nigeria!N12="","",Raw_Nigeria!N12) | P12: =IF(K12="CBAW","Women of child-bearing age","Children") -> Women of child-bearing age | Q12: =IF(J12="NOT USED",1,0) -> 0 | R12: =IF(AND(P12="Children",Q12=0),1,0) -> 0 | S12: =IF(AND(R12=1,J12="Record or Recall",K12="12-23 m"),1,0) -> 0 | T12: =IF(OR(I12="BCG",I12="DTP1",I12="DTP3",I12="POL3",I12="MCV1",I12="FULL"),1,0) -> 0 | U12: =IF(OR(C12="DHS",C12="MICS"),1,0) -> 0 | V12: =IF(O12="",1,0) -> 1 | W12: =IF(M12="",1,0) -> 1 | X12: =COUNTIFS($B$2:$B$1141,B12,$H$2:$H$1141,H12,$I$2:$I$1141,I12,$J$2:$J$1141,J12,$K$2:$K$1141,K12,$L$2:$L$1141,L12) -> 1
A13: =ROW()-1 -> 12 | B13: =IF(Raw_Nigeria!B13="",TRIM(Raw_Nigeria!C13),TRIM(Raw_Nigeria!B13)) -> Status report on revised EPI programme from 1985 to 1989 | C13: =IF(ISNUMBER(SEARCH("Demographic and Health",B13)),"DHS",IF(OR(ISNUMBER(SEARCH("Multiple Indicator Cluster",B13)),ISNUMBER(SEARCH("MICS",B13))),"MICS",IF(ISNUMBER(SEARCH("Immunization Coverage Survey",B13)),"Coverage survey",IF(ISNUMBER(SEARCH("Nutrition",B13)),"Nutrition survey","Other")))) -> Other | D13: =VALUE(LEFT(Raw_Nigeria!D13,4)) -> 1986 | E13: =IF(VALUE(RIGHT(Raw_Nigeria!D13,2))>12,"",VALUE(RIGHT(Raw_Nigeria!D13,2))) | F13: =VALUE(LEFT(Raw_Nigeria!E13,4)) -> 1986 | G13: =IF(VALUE(RIGHT(Raw_Nigeria!E13,2))>12,"",VALUE(RIGHT(Raw_Nigeria!E13,2))) | H13: =Raw_Nigeria!F13 -> 1985 | I13: =UPPER(TRIM(Raw_Nigeria!G13)) -> TT2+ | J13: =Raw_Nigeria!H13 -> Record or Recall | K13: =Raw_Nigeria!L13 -> CBAW | L13: =IF(Raw_Nigeria!K13="","n/a",Raw_Nigeria!K13) -> n/a | M13: =IF(Raw_Nigeria!I13="","",Raw_Nigeria!I13) | N13: =Raw_Nigeria!M13 -> 17.4 | O13: =IF(Raw_Nigeria!N13="","",Raw_Nigeria!N13) | P13: =IF(K13="CBAW","Women of child-bearing age","Children") -> Women of child-bearing age | Q13: =IF(J13="NOT USED",1,0) -> 0 | R13: =IF(AND(P13="Children",Q13=0),1,0) -> 0 | S13: =IF(AND(R13=1,J13="Record or Recall",K13="12-23 m"),1,0) -> 0 | T13: =IF(OR(I13="BCG",I13="DTP1",I13="DTP3",I13="POL3",I13="MCV1",I13="FULL"),1,0) -> 0 | U13: =IF(OR(C13="DHS",C13="MICS"),1,0) -> 0 | V13: =IF(O13="",1,0) -> 1 | W13: =IF(M13="",1,0) -> 1 | X13: =COUNTIFS($B$2:$B$1141,B13,$H$2:$H$1141,H13,$I$2:$I$1141,I13,$J$2:$J$1141,J13,$K$2:$K$1141,K13,$L$2:$L$1141,L13) -> 1
... A1141: =ROW()-1 -> 1140 | B1141: =IF(Raw_Nigeria!B1141="",TRIM(Raw_Nigeria!C1141),TRIM(Raw_Nigeria!B1141)) -> Nigeria Demographic and Health Survey 2024 | C1141: =IF(ISNUMBER(SEARCH("Demographic and Health",B1141)),"DHS",IF(OR(ISNUMBER(SEARCH("Multiple Indicator Cluster",B1141)),ISNUMBER(SEARCH("MICS",B1141))),"MICS",IF(ISNUMBER(SEARCH("Immunization Coverage Survey",B1141)),"Coverage survey",IF(ISNUMBER(SEARCH("Nutrition",B1141)),"Nutrition survey","Other")))) -> DHS | D1141: =VALUE(LEFT(Raw_Nigeria!D1141,4)) -> 2023 | E1141: =IF(VALUE(RIGHT(Raw_Nigeria!D1141,2))>12,"",VALUE(RIGHT(Raw_Nigeria!D1141,2))) -> 12 | F1141: =VALUE(LEFT(Raw_Nigeria!E1141,4)) -> 2024 | G1141: =IF(VALUE(RIGHT(Raw_Nigeria!E1141,2))>12,"",VALUE(RIGHT(Raw_Nigeria!E1141,2))) -> 5 | H1141: =Raw_Nigeria!F1141 -> 2022 | I1141: =UPPER(TRIM(Raw_Nigeria!G1141)) -> YFV | J1141: =Raw_Nigeria!H1141 -> Record or Recall<12m | K1141: =Raw_Nigeria!L1141 -> 12-23 m | L1141: =IF(Raw_Nigeria!K1141="","n/a",Raw_Nigeria!K1141) -> 0-12 m | M1141: =IF(Raw_Nigeria!I1141="","",Raw_Nigeria!I1141) -> 50.2 | N1141: =Raw_Nigeria!M1141 -> 45.5 | O1141: =IF(Raw_Nigeria!N1141="","",Raw_Nigeria!N1141) -> 5121 | P1141: =IF(K1141="CBAW","Women of child-bearing age","Children") -> Children | Q1141: =IF(J1141="NOT USED",1,0) -> 0 | R1141: =IF(AND(P1141="Children",Q1141=0),1,0) -> 1 | S1141: =IF(AND(R1141=1,J1141="Record or Recall",K1141="12-23 m"),1,0) -> 0 | T1141: =IF(OR(I1141="BCG",I1141="DTP1",I1141="DTP3",I1141="POL3",I1141="MCV1",I1141="FULL"),1,0) -> 0 | U1141: =IF(OR(C1141="DHS",C1141="MICS"),1,0) -> 1 | V1141: =IF(O1141="",1,0) -> 0 | W1141: =IF(M1141="",1,0) -> 0 | X1141: =COUNTIFS($B$2:$B$1141,B1141,$H$2:$H$1141,H1141,$I$2:$I$1141,I1141,$J$2:$J$1141,J1141,$K$2:$K$1141,K1141,$L$2:$L$1141,L1141) -> 1

Sheet Cleaning_Log
A1: Step 3 - Cleaning log: missing and inconsistent values
A2: Every count below is a live formula on Raw_Nigeria / Clean_Data. Raw data is never edited; fixes are applied as formulas in Clean_Data.
A4: # | B4: Issue found | C4: Column(s) | D4: Rows affected | E4: Action taken in Clean_Data | F4: Why
A5: 1 | B5: Survey name (English) missing | C5: surveyNameEnglish | D5: =COUNTBLANK(Raw_Nigeria!$B$2:$B$1141) -> 122 | E5: Filled from surveyNameProduction; extra spaces trimmed (Survey column) | F5: These are all pre-2000 surveys. Without the fix 6 older surveys would vanish from any survey-level view.
A6: 2 | B6: Collection month is a placeholder (month code above 12, e.g. '1999-98') | C6: collectBegin / collectEnd | D6: =SUMPRODUCT(--(((Clean_Data!$E$2:$E$1141="")+(Clean_Data!$G$2:$G$1141=""))>0)) -> 58 | E6: Year and month split; placeholder months set to blank | F6: '98' is not a real month. Left as-is it would break any date conversion.
A7: 3 | B7: Sample size (denominator) missing | C7: denominator | D7: =SUM(Clean_Data!$V$2:$V$1141) -> 94 | E7: Kept blank (not imputed); flagged in Missing_Denominator | F7: Needed for margins of error; older surveys lack it, so MoE is only shown where n exists.
A8: 4 | B8: Share of children with vaccination card seen missing | C8: cardsSeen | D8: =SUM(Clean_Data!$W$2:$W$1141) -> 373 | E8: Kept blank (not imputed); flagged in Missing_CardsSeen | F8: Cannot be reconstructed. Do not treat blank as zero.
A9: 5 | B9: Rows about women (tetanus / protection at birth), not children | C9: ageInterview = CBAW | D9: =COUNTIF(Clean_Data!$P$2:$P$1141,"Women of child-bearing age") -> 33 | E9: Labelled Population_Group; excluded from child analysis (In_Scope_Child = 0) | F9: Your project is on childhood immunisation.
A10: 6 | B10: Age at vaccination missing | C10: ageVaccination | D10: =COUNTIF(Clean_Data!$L$2:$L$1141,"n/a") -> 33 | E10: Set to 'n/a' | F10: Same rows as the women's tetanus records above (no age window applies).
A11: 7 | B11: Evidence marked NOT USED by the data producers | C11: evidence | D11: =COUNTIF(Raw_Nigeria!$H$2:$H$1141,"NOT USED") -> 7 | E11: Excluded from analysis (Evidence_Not_Used = 1) | F11: The source itself says these values were not used.
A12: 8 | B12: Vaccine label in mixed case (e.g. Pol3+IPV1) | C12: vaccine | D12: =SUMPRODUCT(--NOT(EXACT(Raw_Nigeria!$G$2:$G$1141,UPPER(Raw_Nigeria!$G$2:$G$1141)))) -> 8 | E12: Upper-cased and trimmed | F12: Prevents the same vaccine being counted as two labels in pivots and Power BI.
A13: 9 | B13: Exact duplicate records (same survey, cohort, vaccine, evidence, ages) | C13: multiple | D13: =COUNTIF(Clean_Data!$X$2:$X$1141,">1") -> 0 | E13: None found; check kept live in Key_Count | F13: Duplicates would double count in averages.
A14: 10 | B14: Coverage outside 0-100% | C14: coverage | D14: =COUNTIF(Clean_Data!$N$2:$N$1141,"<0")+COUNTIF(Clean_Data!$N$2:$N$1141,">100") -> 0 | E14: None found | F14: Impossible values would indicate entry errors.
A15: 11 | B15: All rows flagged CRUDE (unadjusted survey estimates) | C15: validity | D15: =COUNTIF(Raw_Nigeria!$J$2:$J$1141,"CRUDE") -> 1140 | E15: No change; documented | F15: These are survey inputs, not the official WHO/UNICEF estimates. Do not present them as official national coverage.
A16: 12 | B16: Different surveys not directly comparable (design, definitions, FULL definition) | C16: survey | D16: n/a | E16: Analysis uses one standard definition: Record or Recall, children aged 12-23 months (Standard_Comparable = 1) and reports survey families separately | F16: Mixing evidence types and ages would create fake trends.
A18: Totals
B19: Total Nigeria rows in raw file | D19: =COUNTA(Raw_Nigeria!$A$2:$A$1141) -> 1140
B20: Distinct surveys (cleaned names) | D20: =COUNTA(Surveys!A5:A100) -> 22
B21: Rows in the standard comparable set (children, record or recall, 12-23 m) | D21: =SUM(Clean_Data!$S$2:$S$1141) -> 217
B22: ...of which core vaccines (BCG, DTP1, DTP3, POL3, MCV1, FULL) | D22: =SUMPRODUCT(Clean_Data!$S$2:$S$1141,Clean_Data!$T$2:$T$1141) -> 120

Sheet Surveys
A1: Survey list (one row per survey, cleaned names)
A2: Family, year and row counts are formulas on Clean_Data. Survey names are the lookup keys.
A4: Survey | B4: Family | C4: Collect_End_Year | D4: Total_Rows | E4: Child_In_Scope_Rows | F4: Standard_Rows | G4: Has_Core_Standard_Data
A5: Status report on revised EPI programme from 1985 to 1989 | B5: =INDEX(Clean_Data!$C$2:$C$1141,MATCH(A5,Clean_Data!$B$2:$B$1141,0)) -> Other | C5: =INDEX(Clean_Data!$F$2:$F$1141,MATCH(A5,Clean_Data!$B$2:$B$1141,0)) -> 1985 | D5: =COUNTIF(Clean_Data!$B$2:$B$1141,A5) -> 18 | E5: =COUNTIFS(Clean_Data!$B$2:$B$1141,A5,Clean_Data!$R$2:$R$1141,1) -> 12 | F5: =COUNTIFS(Clean_Data!$B$2:$B$1141,A5,Clean_Data!$S$2:$S$1141,1) -> 12 | G5: =IF(COUNTIFS(Clean_Data!$B$2:$B$1141,A5,Clean_Data!$S$2:$S$1141,1,Clean_Data!$T$2:$T$1141,1)>0,"Yes","No") -> Yes
A6: Nigeria Demographic and Health Survey 1990, 1992 | B6: =INDEX(Clean_Data!$C$2:$C$1141,MATCH(A6,Clean_Data!$B$2:$B$1141,0)) -> DHS | C6: =INDEX(Clean_Data!$F$2:$F$1141,MATCH(A6,Clean_Data!$B$2:$B$1141,0)) -> 1990 | D6: =COUNTIF(Clean_Data!$B$2:$B$1141,A6) -> 57 | E6: =COUNTIFS(Clean_Data!$B$2:$B$1141,A6,Clean_Data!$R$2:$R$1141,1) -> 56 | F6: =COUNTIFS(Clean_Data!$B$2:$B$1141,A6,Clean_Data!$S$2:$S$1141,1) -> 7 | G6: =IF(COUNTIFS(Clean_Data!$B$2:$B$1141,A6,Clean_Data!$S$2:$S$1141,1,Clean_Data!$T$2:$T$1141,1)>0,"Yes","No") -> Yes
A7: EPI, Immunization Coverage Survey, 1988 | B7: =INDEX(Clean_Data!$C$2:$C$1141,MATCH(A7,Clean_Data!$B$2:$B$1141,0)) -> Coverage survey | C7: =INDEX(Clean_Data!$F$2:$F$1141,MATCH(A7,Clean_Data!$B$2:$B$1141,0)) -> 1988 | D7: =COUNTIF(Clean_Data!$B$2:$B$1141,A7) -> 15 | E7: =COUNTIFS(Clean_Data!$B$2:$B$1141,A7,Clean_Data!$R$2:$R$1141,1) -> 15 | F7: =COUNTIFS(Clean_Data!$B$2:$B$1141,A7,Clean_Data!$S$2:$S$1141,1) -> 5 | G7: =IF(COUNTIFS(Clean_Data!$B$2:$B$1141,A7,Clean_Data!$S$2:$S$1141,1,Clean_Data!$T$2:$T$1141,1)>0,"Yes","No") -> Yes
A8: WHO/EPI/CEIS/90.1 | B8: =INDEX(Clean_Data!$C$2:$C$1141,MATCH(A8,Clean_Data!$B$2:$B$1141,0)) -> Other | C8: =INDEX(Clean_Data!$F$2:$F$1141,MATCH(A8,Clean_Data!$B$2:$B$1141,0)) -> 1988 | D8: =COUNTIF(Clean_Data!$B$2:$B$1141,A8) -> 1 | E8: =COUNTIFS(Clean_Data!$B$2:$B$1141,A8,Clean_Data!$R$2:$R$1141,1) -> 0 | F8: =COUNTIFS(Clean_Data!$B$2:$B$1141,A8,Clean_Data!$S$2:$S$1141,1) -> 0 | G8: =IF(COUNTIFS(Clean_Data!$B$2:$B$1141,A8,Clean_Data!$S$2:$S$1141,1,Clean_Data!$T$2:$T$1141,1)>0,"Yes","No") -> No
A9: FR of Nigeria Multiple Indicator Cluster Survey 1995 | B9: =INDEX(Clean_Data!$C$2:$C$1141,MATCH(A9,Clean_Data!$B$2:$B$1141,0)) -> MICS | C9: =INDEX(Clean_Data!$F$2:$F$1141,MATCH(A9,Clean_Data!$B$2:$B$1141,0)) -> 1995 | D9: =COUNTIF(Clean_Data!$B$2:$B$1141,A9) -> 15 | E9: =COUNTIFS(Clean_Data!$B$2:$B$1141,A9,Clean_Data!$R$2:$R$1141,1) -> 14 | F9: =COUNTIFS(Clean_Data!$B$2:$B$1141,A9,Clean_Data!$S$2:$S$1141,1) -> 5 | G9: =IF(COUNTIFS(Clean_Data!$B$2:$B$1141,A9,Clean_Data!$S$2:$S$1141,1,Clean_Data!$T$2:$T$1141,1)>0,"Yes","No") -> Yes
A10: MICS Nigeria, 1999 | B10: =INDEX(Clean_Data!$C$2:$C$1141,MATCH(A10,Clean_Data!$B$2:$B$1141,0)) -> MICS | C10: =INDEX(Clean_Data!$F$2:$F$1141,MATCH(A10,Clean_Data!$B$2:$B$1141,0)) -> 1999 | D10: =COUNTIF(Clean_Data!$B$2:$B$1141,A10) -> 16 | E10: =COUNTIFS(Clean_Data!$B$2:$B$1141,A10,Clean_Data!$R$2:$R$1141,1) -> 16 | F10: =COUNTIFS(Clean_Data!$B$2:$B$1141,A10,Clean_Data!$S$2:$S$1141,1) -> 7 | G10: =IF(COUNTIFS(Clean_Data!$B$2:$B$1141,A10,Clean_Data!$S$2:$S$1141,1,Clean_Data!$T$2:$T$1141,1)>0,"Yes","No") -> Yes
A11: Nigeria Demographic and Health Survey 1999, 2000 | B11: =INDEX(Clean_Data!$C$2:$C$1141,MATCH(A11,Clean_Data!$B$2:$B$1141,0)) -> DHS | C11: =INDEX(Clean_Data!$F$2:$F$1141,MATCH(A11,Clean_Data!$B$2:$B$1141,0)) -> 1999 | D11: =COUNTIF(Clean_Data!$B$2:$B$1141,A11) -> 29 | E11: =COUNTIFS(Clean_Data!$B$2:$B$1141,A11,Clean_Data!$R$2:$R$1141,1) -> 28 | F11: =COUNTIFS(Clean_Data!$B$2:$B$1141,A11,Clean_Data!$S$2:$S$1141,1) -> 7 | G11: =IF(COUNTIFS(Clean_Data!$B$2:$B$1141,A11,Clean_Data!$S$2:$S$1141,1,Clean_Data!$T$2:$T$1141,1)>0,"Yes","No") -> Yes
A12: Nigeria Demographic and Health Survey 2003 | B12: =INDEX(Clean_Data!$C$2:$C$1141,MATCH(A12,Clean_Data!$B$2:$B$1141,0)) -> DHS | C12: =INDEX(Clean_Data!$F$2:$F$1141,MATCH(A12,Clean_Data!$B$2:$B$1141,0)) -> 2003 | D12: =COUNTIF(Clean_Data!$B$2:$B$1141,A12) -> 29 | E12: =COUNTIFS(Clean_Data!$B$2:$B$1141,A12,Clean_Data!$R$2:$R$1141,1) -> 28 | F12: =COUNTIFS(Clean_Data!$B$2:$B$1141,A12,Clean_Data!$S$2:$S$1141,1) -> 7 | G12: =IF(COUNTIFS(Clean_Data!$B$2:$B$1141,A12,Clean_Data!$S$2:$S$1141,1,Clean_Data!$T$2:$T$1141,1)>0,"Yes","No") -> Yes
A13: Nigeria National Immunization Coverage Survey 2003 | B13: =INDEX(Clean_Data!$C$2:$C$1141,MATCH(A13,Clean_Data!$B$2:$B$1141,0)) -> Coverage survey | C13: =INDEX(Clean_Data!$F$2:$F$1141,MATCH(A13,Clean_Data!$B$2:$B$1141,0)) -> 2003 | D13: =COUNTIF(Clean_Data!$B$2:$B$1141,A13) -> 8 | E13: =COUNTIFS(Clean_Data!$B$2:$B$1141,A13,Clean_Data!$R$2:$R$1141,1) -> 7 | F13: =COUNTIFS(Clean_Data!$B$2:$B$1141,A13,Clean_Data!$S$2:$S$1141,1) -> 7 | G13: =IF(COUNTIFS(Clean_Data!$B$2:$B$1141,A13,Clean_Data!$S$2:$S$1141,1,Clean_Data!$T$2:$T$1141,1)>0,"Yes","No") -> Yes
A14: Nigeria National Immunization Coverage Survey (2006) | B14: =INDEX(Clean_Data!$C$2:$C$1141,MATCH(A14,Clean_Data!$B$2:$B$1141,0)) -> Coverage survey | C14: =INDEX(Clean_Data!$F$2:$F$1141,MATCH(A14,Clean_Data!$B$2:$B$1141,0)) -> 2006 | D14: =COUNTIF(Clean_Data!$B$2:$B$1141,A14) -> 21 | E14: =COUNTIFS(Clean_Data!$B$2:$B$1141,A14,Clean_Data!$R$2:$R$1141,1) -> 21 | F14: =COUNTIFS(Clean_Data!$B$2:$B$1141,A14,Clean_Data!$S$2:$S$1141,1) -> 11 | G14: =IF(COUNTIFS(Clean_Data!$B$2:$B$1141,A14,Clean_Data!$S$2:$S$1141,1,Clean_Data!$T$2:$T$1141,1)>0,"Yes","No") -> Yes
A15: Nigeria Multiple Indicator Cluster Survey 2007 | B15: =INDEX(Clean_Data!$C$2:$C$1141,MATCH(A15,Clean_Data!$B$2:$B$1141,0)) -> MICS | C15: =INDEX(Clean_Data!$F$2:$F$1141,MATCH(A15,Clean_Data!$B$2:$B$1141,0)) -> 2007 | D15: =COUNTIF(Clean_Data!$B$2:$B$1141,A15) -> 30 | E15: =COUNTIFS(Clean_Data!$B$2:$B$1141,A15,Clean_Data!$R$2:$R$1141,1) -> 28 | F15: =COUNTIFS(Clean_Data!$B$2:$B$1141,A15,Clean_Data!$S$2:$S$1141,1) -> 7 | G15: =IF(COUNTIFS(Clean_Data!$B$2:$B$1141,A15,Clean_Data!$S$2:$S$1141,1,Clean_Data!$T$2:$T$1141,1)>0,"Yes","No") -> Yes
A16: Nigeria Demographic and Health Survey 2008 | B16: =INDEX(Clean_Data!$C$2:$C$1141,MATCH(A16,Clean_Data!$B$2:$B$1141,0)) -> DHS | C16: =INDEX(Clean_Data!$F$2:$F$1141,MATCH(A16,Clean_Data!$B$2:$B$1141,0)) -> 2008 | D16: =COUNTIF(Clean_Data!$B$2:$B$1141,A16) -> 30 | E16: =COUNTIFS(Clean_Data!$B$2:$B$1141,A16,Clean_Data!$R$2:$R$1141,1) -> 28 | F16: =COUNTIFS(Clean_Data!$B$2:$B$1141,A16,Clean_Data!$S$2:$S$1141,1) -> 7 | G16: =IF(COUNTIFS(Clean_Data!$B$2:$B$1141,A16,Clean_Data!$S$2:$S$1141,1,Clean_Data!$T$2:$T$1141,1)>0,"Yes","No") -> Yes
... A26: Nigeria Demographic and Health Survey 2024 | B26: =INDEX(Clean_Data!$C$2:$C$1141,MATCH(A26,Clean_Data!$B$2:$B$1141,0)) -> DHS | C26: =INDEX(Clean_Data!$F$2:$F$1141,MATCH(A26,Clean_Data!$B$2:$B$1141,0)) -> 2024 | D26: =COUNTIF(Clean_Data!$B$2:$B$1141,A26) -> 234 | E26: =COUNTIFS(Clean_Data!$B$2:$B$1141,A26,Clean_Data!$R$2:$R$1141,1) -> 232 | F26: =COUNTIFS(Clean_Data!$B$2:$B$1141,A26,Clean_Data!$S$2:$S$1141,1) -> 29 | G26: =IF(COUNTIFS(Clean_Data!$B$2:$B$1141,A26,Clean_Data!$S$2:$S$1141,1,Clean_Data!$T$2:$T$1141,1)>0,"Yes","No") -> Yes

Sheet Coverage
A1: Step 4 - Vaccination coverage by survey (children aged 12-23 months, card or caregiver recall)
A2: Coverage % = survey-reported share of children vaccinated. Each row is one survey and birth cohort. Values are AVERAGEIFS lookups on Clean_Data (Standard_Comparable = 1).
A3: Design effect (assumption) | B3: 2 | C3: ASSUMPTION, not in the source file. Clustered surveys have wider error than simple random samples; set from the survey report if you have it. Drives the margin of error in column L only.
A5: Survey | B5: Family | C5: Cohort_Year | D5: Collect_End_Year | E5: BCG | F5: DTP1 | G5: DTP3 | H5: POL3 | I5: MCV1 | J5: FULL | K5: DTP3_Sample_n | L5: DTP3_95%_Margin_pp | M5: DTP_Dropout_% | N5: BCG_to_MCV1_Dropout_% | O5: Zero_Dose_Proxy_% | P5: Not_Fully_Vaccinated_% | Q5: Check_DTP3_Rows
A6: Status report on revised EPI programme from 1985 to 1989 | B6: =INDEX(Clean_Data!$C$2:$C$1141,MATCH(A6,Clean_Data!$B$2:$B$1141,0)) -> Other | C6: 1984 | D6: =INDEX(Clean_Data!$F$2:$F$1141,MATCH(A6,Clean_Data!$B$2:$B$1141,0)) -> 1985 | E6: =IFERROR(AVERAGEIFS(Clean_Data!$N$2:$N$1141,Clean_Data!$B$2:$B$1141,$A6,Clean_Data!$H$2:$H$1141,$C6,Clean_Data!$I$2:$I$1141,E$5,Clean_Data!$S$2:$S$1141,1),"") -> 16.5 | F6: =IFERROR(AVERAGEIFS(Clean_Data!$N$2:$N$1141,Clean_Data!$B$2:$B$1141,$A6,Clean_Data!$H$2:$H$1141,$C6,Clean_Data!$I$2:$I$1141,F$5,Clean_Data!$S$2:$S$1141,1),"") | G6: =IFERROR(AVERAGEIFS(Clean_Data!$N$2:$N$1141,Clean_Data!$B$2:$B$1141,$A6,Clean_Data!$H$2:$H$1141,$C6,Clean_Data!$I$2:$I$1141,G$5,Clean_Data!$S$2:$S$1141,1),"") -> 8.9 | H6: =IFERROR(AVERAGEIFS(Clean_Data!$N$2:$N$1141,Clean_Data!$B$2:$B$1141,$A6,Clean_Data!$H$2:$H$1141,$C6,Clean_Data!$I$2:$I$1141,H$5,Clean_Data!$S$2:$S$1141,1),"") -> 8.1 | I6: =IFERROR(AVERAGEIFS(Clean_Data!$N$2:$N$1141,Clean_Data!$B$2:$B$1141,$A6,Clean_Data!$H$2:$H$1141,$C6,Clean_Data!$I$2:$I$1141,I$5,Clean_Data!$S$2:$S$1141,1),"") -> 9.1 | J6: =IFERROR(AVERAGEIFS(Clean_Data!$N$2:$N$1141,Clean_Data!$B$2:$B$1141,$A6,Clean_Data!$H$2:$H$1141,$C6,Clean_Data!$I$2:$I$1141,J$5,Clean_Data!$S$2:$S$1141,1),"") | K6: =IFERROR(AVERAGEIFS(Clean_Data!$O$2:$O$1141,Clean_Data!$B$2:$B$1141,$A6,Clean_Data!$H$2:$H$1141,$C6,Clean_Data!$I$2:$I$1141,"DTP3",Clean_Data!$S$2:$S$1141,1),"") | L6: =IF(AND(ISNUMBER(G6),ISNUMBER(K6)),1.96*SQRT((G6/100)*(1-G6/100)/(K6/$B$3))*100,"") | M6: =IF(AND(ISNUMBER(F6),ISNUMBER(G6)),IF(F6>0,(F6-G6)/F6*100,""),"") | N6: =IF(AND(ISNUMBER(E6),ISNUMBER(I6)),IF(E6>0,(E6-I6)/E6*100,""),"") -> 44.848485 | O6: =IF(ISNUMBER(F6),100-F6,"") | P6: =IF(ISNUMBER(J6),100-J6,"") | Q6: =COUNTIFS(Clean_Data!$B$2:$B$1141,$A6,Clean_Data!$H$2:$H$1141,$C6,Clean_Data!$I$2:$I$1141,"DTP3",Clean_Data!$S$2:$S$1141,1) -> 1
A7: Status report on revised EPI programme from 1985 to 1989 | B7: =INDEX(Clean_Data!$C$2:$C$1141,MATCH(A7,Clean_Data!$B$2:$B$1141,0)) -> Other | C7: 1985 | D7: =INDEX(Clean_Data!$F$2:$F$1141,MATCH(A7,Clean_Data!$B$2:$B$1141,0)) -> 1985 | E7: =IFERROR(AVERAGEIFS(Clean_Data!$N$2:$N$1141,Clean_Data!$B$2:$B$1141,$A7,Clean_Data!$H$2:$H$1141,$C7,Clean_Data!$I$2:$I$1141,E$5,Clean_Data!$S$2:$S$1141,1),"") -> 28.3 | F7: =IFERROR(AVERAGEIFS(Clean_Data!$N$2:$N$1141,Clean_Data!$B$2:$B$1141,$A7,Clean_Data!$H$2:$H$1141,$C7,Clean_Data!$I$2:$I$1141,F$5,Clean_Data!$S$2:$S$1141,1),"") | G7: =IFERROR(AVERAGEIFS(Clean_Data!$N$2:$N$1141,Clean_Data!$B$2:$B$1141,$A7,Clean_Data!$H$2:$H$1141,$C7,Clean_Data!$I$2:$I$1141,G$5,Clean_Data!$S$2:$S$1141,1),"") -> 15.9 | H7: =IFERROR(AVERAGEIFS(Clean_Data!$N$2:$N$1141,Clean_Data!$B$2:$B$1141,$A7,Clean_Data!$H$2:$H$1141,$C7,Clean_Data!$I$2:$I$1141,H$5,Clean_Data!$S$2:$S$1141,1),"") -> 16.3 | I7: =IFERROR(AVERAGEIFS(Clean_Data!$N$2:$N$1141,Clean_Data!$B$2:$B$1141,$A7,Clean_Data!$H$2:$H$1141,$C7,Clean_Data!$I$2:$I$1141,I$5,Clean_Data!$S$2:$S$1141,1),"") -> 17.2 | J7: =IFERROR(AVERAGEIFS(Clean_Data!$N$2:$N$1141,Clean_Data!$B$2:$B$1141,$A7,Clean_Data!$H$2:$H$1141,$C7,Clean_Data!$I$2:$I$1141,J$5,Clean_Data!$S$2:$S$1141,1),"") | K7: =IFERROR(AVERAGEIFS(Clean_Data!$O$2:$O$1141,Clean_Data!$B$2:$B$1141,$A7,Clean_Data!$H$2:$H$1141,$C7,Clean_Data!$I$2:$I$1141,"DTP3",Clean_Data!$S$2:$S$1141,1),"") | L7: =IF(AND(ISNUMBER(G7),ISNUMBER(K7)),1.96*SQRT((G7/100)*(1-G7/100)/(K7/$B$3))*100,"") | M7: =IF(AND(ISNUMBER(F7),ISNUMBER(G7)),IF(F7>0,(F7-G7)/F7*100,""),"") | N7: =IF(AND(ISNUMBER(E7),ISNUMBER(I7)),IF(E7>0,(E7-I7)/E7*100,""),"") -> 39.222615 | O7: =IF(ISNUMBER(F7),100-F7,"") | P7: =IF(ISNUMBER(J7),100-J7,"") | Q7: =COUNTIFS(Clean_Data!$B$2:$B$1141,$A7,Clean_Data!$H$2:$H$1141,$C7,Clean_Data!$I$2:$I$1141,"DTP3",Clean_Data!$S$2:$S$1141,1) -> 1
A8: Status report on revised EPI programme from 1985 to 1989 | B8: =INDEX(Clean_Data!$C$2:$C$1141,MATCH(A8,Clean_Data!$B$2:$B$1141,0)) -> Other | C8: 1986 | D8: =INDEX(Clean_Data!$F$2:$F$1141,MATCH(A8,Clean_Data!$B$2:$B$1141,0)) -> 1985 | E8: =IFERROR(AVERAGEIFS(Clean_Data!$N$2:$N$1141,Clean_Data!$B$2:$B$1141,$A8,Clean_Data!$H$2:$H$1141,$C8,Clean_Data!$I$2:$I$1141,E$5,Clean_Data!$S$2:$S$1141,1),"") -> 40 | F8: =IFERROR(AVERAGEIFS(Clean_Data!$N$2:$N$1141,Clean_Data!$B$2:$B$1141,$A8,Clean_Data!$H$2:$H$1141,$C8,Clean_Data!$I$2:$I$1141,F$5,Clean_Data!$S$2:$S$1141,1),"") | G8: =IFERROR(AVERAGEIFS(Clean_Data!$N$2:$N$1141,Clean_Data!$B$2:$B$1141,$A8,Clean_Data!$H$2:$H$1141,$C8,Clean_Data!$I$2:$I$1141,G$5,Clean_Data!$S$2:$S$1141,1),"") -> 21.5 | H8: =IFERROR(AVERAGEIFS(Clean_Data!$N$2:$N$1141,Clean_Data!$B$2:$B$1141,$A8,Clean_Data!$H$2:$H$1141,$C8,Clean_Data!$I$2:$I$1141,H$5,Clean_Data!$S$2:$S$1141,1),"") -> 20.7 | I8: =IFERROR(AVERAGEIFS(Clean_Data!$N$2:$N$1141,Clean_Data!$B$2:$B$1141,$A8,Clean_Data!$H$2:$H$1141,$C8,Clean_Data!$I$2:$I$1141,I$5,Clean_Data!$S$2:$S$1141,1),"") -> 28 | J8: =IFERROR(AVERAGEIFS(Clean_Data!$N$2:$N$1141,Clean_Data!$B$2:$B$1141,$A8,Clean_Data!$H$2:$H$1141,$C8,Clean_Data!$I$2:$I$1141,J$5,Clean_Data!$S$2:$S$1141,1),"") | K8: =IFERROR(AVERAGEIFS(Clean_Data!$O$2:$O$1141,Clean_Data!$B$2:$B$1141,$A8,Clean_Data!$H$2:$H$1141,$C8,Clean_Data!$I$2:$I$1141,"DTP3",Clean_Data!$S$2:$S$1141,1),"") | L8: =IF(AND(ISNUMBER(G8),ISNUMBER(K8)),1.96*SQRT((G8/100)*(1-G8/100)/(K8/$B$3))*100,"") | M8: =IF(AND(ISNUMBER(F8),ISNUMBER(G8)),IF(F8>0,(F8-G8)/F8*100,""),"") | N8: =IF(AND(ISNUMBER(E8),ISNUMBER(I8)),IF(E8>0,(E8-I8)/E8*100,""),"") -> 30 | O8: =IF(ISNUMBER(F8),100-F8,"") | P8: =IF(ISNUMBER(J8),100-J8,"") | Q8: =COUNTIFS(Clean_Data!$B$2:$B$1141,$A8,Clean_Data!$H$2:$H$1141,$C8,Clean_Data!$I$2:$I$1141,"DTP3",Clean_Data!$S$2:$S$1141,1) -> 1
A9: EPI, Immunization Coverage Survey, 1988 | B9: =INDEX(Clean_Data!$C$2:$C$1141,MATCH(A9,Clean_Data!$B$2:$B$1141,0)) -> Coverage survey | C9: 1987 | D9: =INDEX(Clean_Data!$F$2:$F$1141,MATCH(A9,Clean_Data!$B$2:$B$1141,0)) -> 1988 | E9: =IFERROR(AVERAGEIFS(Clean_Data!$N$2:$N$1141,Clean_Data!$B$2:$B$1141,$A9,Clean_Data!$H$2:$H$1141,$C9,Clean_Data!$I$2:$I$1141,E$5,Clean_Data!$S$2:$S$1141,1),"") -> 72.2 | F9: =IFERROR(AVERAGEIFS(Clean_Data!$N$2:$N$1141,Clean_Data!$B$2:$B$1141,$A9,Clean_Data!$H$2:$H$1141,$C9,Clean_Data!$I$2:$I$1141,F$5,Clean_Data!$S$2:$S$1141,1),"") | G9: =IFERROR(AVERAGEIFS(Clean_Data!$N$2:$N$1141,Clean_Data!$B$2:$B$1141,$A9,Clean_Data!$H$2:$H$1141,$C9,Clean_Data!$I$2:$I$1141,G$5,Clean_Data!$S$2:$S$1141,1),"") -> 57.8 | H9: =IFERROR(AVERAGEIFS(Clean_Data!$N$2:$N$1141,Clean_Data!$B$2:$B$1141,$A9,Clean_Data!$H$2:$H$1141,$C9,Clean_Data!$I$2:$I$1141,H$5,Clean_Data!$S$2:$S$1141,1),"") -> 57 | I9: =IFERROR(AVERAGEIFS(Clean_Data!$N$2:$N$1141,Clean_Data!$B$2:$B$1141,$A9,Clean_Data!$H$2:$H$1141,$C9,Clean_Data!$I$2:$I$1141,I$5,Clean_Data!$S$2:$S$1141,1),"") -> 59.2 | J9: =IFERROR(AVERAGEIFS(Clean_Data!$N$2:$N$1141,Clean_Data!$B$2:$B$1141,$A9,Clean_Data!$H$2:$H$1141,$C9,Clean_Data!$I$2:$I$1141,J$5,Clean_Data!$S$2:$S$1141,1),"") -> 37.5 | K9: =IFERROR(AVERAGEIFS(Clean_Data!$O$2:$O$1141,Clean_Data!$B$2:$B$1141,$A9,Clean_Data!$H$2:$H$1141,$C9,Clean_Data!$I$2:$I$1141,"DTP3",Clean_Data!$S$2:$S$1141,1),"") -> 9240 | L9: =IF(AND(ISNUMBER(G9),ISNUMBER(K9)),1.96*SQRT((G9/100)*(1-G9/100)/(K9/$B$3))*100,"") -> 1.4241483 | M9: =IF(AND(ISNUMBER(F9),ISNUMBER(G9)),IF(F9>0,(F9-G9)/F9*100,""),"") | N9: =IF(AND(ISNUMBER(E9),ISNUMBER(I9)),IF(E9>0,(E9-I9)/E9*100,""),"") -> 18.00554 | O9: =IF(ISNUMBER(F9),100-F9,"") | P9: =IF(ISNUMBER(J9),100-J9,"") -> 62.5 | Q9: =COUNTIFS(Clean_Data!$B$2:$B$1141,$A9,Clean_Data!$H$2:$H$1141,$C9,Clean_Data!$I$2:$I$1141,"DTP3",Clean_Data!$S$2:$S$1141,1) -> 1
A10: Nigeria Demographic and Health Survey 1990, 1992 | B10: =INDEX(Clean_Data!$C$2:$C$1141,MATCH(A10,Clean_Data!$B$2:$B$1141,0)) -> DHS | C10: 1989 | D10: =INDEX(Clean_Data!$F$2:$F$1141,MATCH(A10,Clean_Data!$B$2:$B$1141,0)) -> 1990 | E10: =IFERROR(AVERAGEIFS(Clean_Data!$N$2:$N$1141,Clean_Data!$B$2:$B$1141,$A10,Clean_Data!$H$2:$H$1141,$C10,Clean_Data!$I$2:$I$1141,E$5,Clean_Data!$S$2:$S$1141,1),"") -> 60.7 | F10: =IFERROR(AVERAGEIFS(Clean_Data!$N$2:$N$1141,Clean_Data!$B$2:$B$1141,$A10,Clean_Data!$H$2:$H$1141,$C10,Clean_Data!$I$2:$I$1141,F$5,Clean_Data!$S$2:$S$1141,1),"") -> 59.2 | G10: =IFERROR(AVERAGEIFS(Clean_Data!$N$2:$N$1141,Clean_Data!$B$2:$B$1141,$A10,Clean_Data!$H$2:$H$1141,$C10,Clean_Data!$I$2:$I$1141,G$5,Clean_Data!$S$2:$S$1141,1),"") -> 33.3 | H10: =IFERROR(AVERAGEIFS(Clean_Data!$N$2:$N$1141,Clean_Data!$B$2:$B$1141,$A10,Clean_Data!$H$2:$H$1141,$C10,Clean_Data!$I$2:$I$1141,H$5,Clean_Data!$S$2:$S$1141,1),"") -> 33.4 | I10: =IFERROR(AVERAGEIFS(Clean_Data!$N$2:$N$1141,Clean_Data!$B$2:$B$1141,$A10,Clean_Data!$H$2:$H$1141,$C10,Clean_Data!$I$2:$I$1141,I$5,Clean_Data!$S$2:$S$1141,1),"") -> 46 | J10: =IFERROR(AVERAGEIFS(Clean_Data!$N$2:$N$1141,Clean_Data!$B$2:$B$1141,$A10,Clean_Data!$H$2:$H$1141,$C10,Clean_Data!$I$2:$I$1141,J$5,Clean_Data!$S$2:$S$1141,1),"") -> 29.6 | K10: =IFERROR(AVERAGEIFS(Clean_Data!$O$2:$O$1141,Clean_Data!$B$2:$B$1141,$A10,Clean_Data!$H$2:$H$1141,$C10,Clean_Data!$I$2:$I$1141,"DTP3",Clean_Data!$S$2:$S$1141,1),"") -> 1380 | L10: =IF(AND(ISNUMBER(G10),ISNUMBER(K10)),1.96*SQRT((G10/100)*(1-G10/100)/(K10/$B$3))*100,"") -> 3.5165481 | M10: =IF(AND(ISNUMBER(F10),ISNUMBER(G10)),IF(F10>0,(F10-G10)/F10*100,""),"") -> 43.75 | N10: =IF(AND(ISNUMBER(E10),ISNUMBER(I10)),IF(E10>0,(E10-I10)/E10*100,""),"") -> 24.217463 | O10: =IF(ISNUMBER(F10),100-F10,"") -> 40.8 | P10: =IF(ISNUMBER(J10),100-J10,"") -> 70.4 | Q10: =COUNTIFS(Clean_Data!$B$2:$B$1141,$A10,Clean_Data!$H$2:$H$1141,$C10,Clean_Data!$I$2:$I$1141,"DTP3",Clean_Data!$S$2:$S$1141,1) -> 1
A11: FR of Nigeria Multiple Indicator Cluster Survey 1995 | B11: =INDEX(Clean_Data!$C$2:$C$1141,MATCH(A11,Clean_Data!$B$2:$B$1141,0)) -> MICS | C11: 1994 | D11: =INDEX(Clean_Data!$F$2:$F$1141,MATCH(A11,Clean_Data!$B$2:$B$1141,0)) -> 1995 | E11: =IFERROR(AVERAGEIFS(Clean_Data!$N$2:$N$1141,Clean_Data!$B$2:$B$1141,$A11,Clean_Data!$H$2:$H$1141,$C11,Clean_Data!$I$2:$I$1141,E$5,Clean_Data!$S$2:$S$1141,1),"") -> 52 | F11: =IFERROR(AVERAGEIFS(Clean_Data!$N$2:$N$1141,Clean_Data!$B$2:$B$1141,$A11,Clean_Data!$H$2:$H$1141,$C11,Clean_Data!$I$2:$I$1141,F$5,Clean_Data!$S$2:$S$1141,1),"") | G11: =IFERROR(AVERAGEIFS(Clean_Data!$N$2:$N$1141,Clean_Data!$B$2:$B$1141,$A11,Clean_Data!$H$2:$H$1141,$C11,Clean_Data!$I$2:$I$1141,G$5,Clean_Data!$S$2:$S$1141,1),"") -> 27.5 | H11: =IFERROR(AVERAGEIFS(Clean_Data!$N$2:$N$1141,Clean_Data!$B$2:$B$1141,$A11,Clean_Data!$H$2:$H$1141,$C11,Clean_Data!$I$2:$I$1141,H$5,Clean_Data!$S$2:$S$1141,1),"") -> 27.5 | I11: =IFERROR(AVERAGEIFS(Clean_Data!$N$2:$N$1141,Clean_Data!$B$2:$B$1141,$A11,Clean_Data!$H$2:$H$1141,$C11,Clean_Data!$I$2:$I$1141,I$5,Clean_Data!$S$2:$S$1141,1),"") -> 39.9 | J11: =IFERROR(AVERAGEIFS(Clean_Data!$N$2:$N$1141,Clean_Data!$B$2:$B$1141,$A11,Clean_Data!$H$2:$H$1141,$C11,Clean_Data!$I$2:$I$1141,J$5,Clean_Data!$S$2:$S$1141,1),"") -> 22 | K11: =IFERROR(AVERAGEIFS(Clean_Data!$O$2:$O$1141,Clean_Data!$B$2:$B$1141,$A11,Clean_Data!$H$2:$H$1141,$C11,Clean_Data!$I$2:$I$1141,"DTP3",Clean_Data!$S$2:$S$1141,1),"") -> 1743 | L11: =IF(AND(ISNUMBER(G11),ISNUMBER(K11)),1.96*SQRT((G11/100)*(1-G11/100)/(K11/$B$3))*100,"") -> 2.9645428 | M11: =IF(AND(ISNUMBER(F11),ISNUMBER(G11)),IF(F11>0,(F11-G11)/F11*100,""),"") | N11: =IF(AND(ISNUMBER(E11),ISNUMBER(I11)),IF(E11>0,(E11-I11)/E11*100,""),"") -> 23.269231 | O11: =IF(ISNUMBER(F11),100-F11,"") | P11: =IF(ISNUMBER(J11),100-J11,"") -> 78 | Q11: =COUNTIFS(Clean_Data!$B$2:$B$1141,$A11,Clean_Data!$H$2:$H$1141,$C11,Clean_Data!$I$2:$I$1141,"DTP3",Clean_Data!$S$2:$S$1141,1) -> 1
A12: MICS Nigeria, 1999 | B12: =INDEX(Clean_Data!$C$2:$C$1141,MATCH(A12,Clean_Data!$B$2:$B$1141,0)) -> MICS | C12: 1998 | D12: =INDEX(Clean_Data!$F$2:$F$1141,MATCH(A12,Clean_Data!$B$2:$B$1141,0)) -> 1999 | E12: =IFERROR(AVERAGEIFS(Clean_Data!$N$2:$N$1141,Clean_Data!$B$2:$B$1141,$A12,Clean_Data!$H$2:$H$1141,$C12,Clean_Data!$I$2:$I$1141,E$5,Clean_Data!$S$2:$S$1141,1),"") -> 43 | F12: =IFERROR(AVERAGEIFS(Clean_Data!$N$2:$N$1141,Clean_Data!$B$2:$B$1141,$A12,Clean_Data!$H$2:$H$1141,$C12,Clean_Data!$I$2:$I$1141,F$5,Clean_Data!$S$2:$S$1141,1),"") -> 41.1 | G12: =IFERROR(AVERAGEIFS(Clean_Data!$N$2:$N$1141,Clean_Data!$B$2:$B$1141,$A12,Clean_Data!$H$2:$H$1141,$C12,Clean_Data!$I$2:$I$1141,G$5,Clean_Data!$S$2:$S$1141,1),"") -> 23.4 | H12: =IFERROR(AVERAGEIFS(Clean_Data!$N$2:$N$1141,Clean_Data!$B$2:$B$1141,$A12,Clean_Data!$H$2:$H$1141,$C12,Clean_Data!$I$2:$I$1141,H$5,Clean_Data!$S$2:$S$1141,1),"") -> 18.8 | I12: =IFERROR(AVERAGEIFS(Clean_Data!$N$2:$N$1141,Clean_Data!$B$2:$B$1141,$A12,Clean_Data!$H$2:$H$1141,$C12,Clean_Data!$I$2:$I$1141,I$5,Clean_Data!$S$2:$S$1141,1),"") -> 35 | J12: =IFERROR(AVERAGEIFS(Clean_Data!$N$2:$N$1141,Clean_Data!$B$2:$B$1141,$A12,Clean_Data!$H$2:$H$1141,$C12,Clean_Data!$I$2:$I$1141,J$5,Clean_Data!$S$2:$S$1141,1),"") -> 13.3 | K12: =IFERROR(AVERAGEIFS(Clean_Data!$O$2:$O$1141,Clean_Data!$B$2:$B$1141,$A12,Clean_Data!$H$2:$H$1141,$C12,Clean_Data!$I$2:$I$1141,"DTP3",Clean_Data!$S$2:$S$1141,1),"") -> 2841 | L12: =IF(AND(ISNUMBER(G12),ISNUMBER(K12)),1.96*SQRT((G12/100)*(1-G12/100)/(K12/$B$3))*100,"") -> 2.2016981 | M12: =IF(AND(ISNUMBER(F12),ISNUMBER(G12)),IF(F12>0,(F12-G12)/F12*100,""),"") -> 43.065693 | N12: =IF(AND(ISNUMBER(E12),ISNUMBER(I12)),IF(E12>0,(E12-I12)/E12*100,""),"") -> 18.604651 | O12: =IF(ISNUMBER(F12),100-F12,"") -> 58.9 | P12: =IF(ISNUMBER(J12),100-J12,"") -> 86.7 | Q12: =COUNTIFS(Clean_Data!$B$2:$B$1141,$A12,Clean_Data!$H$2:$H$1141,$C12,Clean_Data!$I$2:$I$1141,"DTP3",Clean_Data!$S$2:$S$1141,1) -> 1
A13: Nigeria Demographic and Health Survey 1999, 2000 | B13: =INDEX(Clean_Data!$C$2:$C$1141,MATCH(A13,Clean_Data!$B$2:$B$1141,0)) -> DHS | C13: 1998 | D13: =INDEX(Clean_Data!$F$2:$F$1141,MATCH(A13,Clean_Data!$B$2:$B$1141,0)) -> 1999 | E13: =IFERROR(AVERAGEIFS(Clean_Data!$N$2:$N$1141,Clean_Data!$B$2:$B$1141,$A13,Clean_Data!$H$2:$H$1141,$C13,Clean_Data!$I$2:$I$1141,E$5,Clean_Data!$S$2:$S$1141,1),"") -> 53.8 | F13: =IFERROR(AVERAGEIFS(Clean_Data!$N$2:$N$1141,Clean_Data!$B$2:$B$1141,$A13,Clean_Data!$H$2:$H$1141,$C13,Clean_Data!$I$2:$I$1141,F$5,Clean_Data!$S$2:$S$1141,1),"") -> 47.4 | G13: =IFERROR(AVERAGEIFS(Clean_Data!$N$2:$N$1141,Clean_Data!$B$2:$B$1141,$A13,Clean_Data!$H$2:$H$1141,$C13,Clean_Data!$I$2:$I$1141,G$5,Clean_Data!$S$2:$S$1141,1),"") -> 26.3 | H13: =IFERROR(AVERAGEIFS(Clean_Data!$N$2:$N$1141,Clean_Data!$B$2:$B$1141,$A13,Clean_Data!$H$2:$H$1141,$C13,Clean_Data!$I$2:$I$1141,H$5,Clean_Data!$S$2:$S$1141,1),"") -> 24.8 | I13: =IFERROR(AVERAGEIFS(Clean_Data!$N$2:$N$1141,Clean_Data!$B$2:$B$1141,$A13,Clean_Data!$H$2:$H$1141,$C13,Clean_Data!$I$2:$I$1141,I$5,Clean_Data!$S$2:$S$1141,1),"") -> 40.5 | J13: =IFERROR(AVERAGEIFS(Clean_Data!$N$2:$N$1141,Clean_Data!$B$2:$B$1141,$A13,Clean_Data!$H$2:$H$1141,$C13,Clean_Data!$I$2:$I$1141,J$5,Clean_Data!$S$2:$S$1141,1),"") -> 16.8 | K13: =IFERROR(AVERAGEIFS(Clean_Data!$O$2:$O$1141,Clean_Data!$B$2:$B$1141,$A13,Clean_Data!$H$2:$H$1141,$C13,Clean_Data!$I$2:$I$1141,"DTP3",Clean_Data!$S$2:$S$1141,1),"") -> 1161 | L13: =IF(AND(ISNUMBER(G13),ISNUMBER(K13)),1.96*SQRT((G13/100)*(1-G13/100)/(K13/$B$3))*100,"") -> 3.5815134 | M13: =IF(AND(ISNUMBER(F13),ISNUMBER(G13)),IF(F13>0,(F13-G13)/F13*100,""),"") -> 44.514768 | N13: =IF(AND(ISNUMBER(E13),ISNUMBER(I13)),IF(E13>0,(E13-I13)/E13*100,""),"") -> 24.72119 | O13: =IF(ISNUMBER(F13),100-F13,"") -> 52.6 | P13: =IF(ISNUMBER(J13),100-J13,"") -> 83.2 | Q13: =COUNTIFS(Clean_Data!$B$2:$B$1141,$A13,Clean_Data!$H$2:$H$1141,$C13,Clean_Data!$I$2:$I$1141,"DTP3",Clean_Data!$S$2:$S$1141,1) -> 1
